Internal Server Error: /yudas/list
Traceback (most recent call last):
  File "C:\Users\beyza.ozkara\ArslanDjango\env\Lib\site-packages\django\db\backends\utils.py", line 89, in _execute
    return self.cursor.execute(sql, params)
           ^^^^^^^^^^^^^^^^^^^^^^^^^^^^^^^^
psycopg2.errors.UndefinedColumn: column ArslanTakipApp_yudaform.Silindi does not exist
LINE 1: ...", "ArslanTakipApp_yudaform"."PaketlemeAciklama", "ArslanTak...
                                                             ^


The above exception was the direct cause of the following exception:

Traceback (most recent call last):
  File "C:\Users\beyza.ozkara\ArslanDjango\env\Lib\site-packages\django\core\handlers\exception.py", line 55, in inner
    response = get_response(request)
               ^^^^^^^^^^^^^^^^^^^^^
  File "C:\Users\beyza.ozkara\ArslanDjango\env\Lib\site-packages\django\core\handlers\base.py", line 197, in _get_response
    response = wrapped_callback(request, *callback_args, **callback_kwargs)
               ^^^^^^^^^^^^^^^^^^^^^^^^^^^^^^^^^^^^^^^^^^^^^^^^^^^^^^^^^^^^
  File "C:\Users\beyza.ozkara\ArslanDjango\env\ArslanProject\ArslanTakipApp\views.py", line 1203, in yudas_list
    yudaList = list(filtered_yudas.values()[offset:limit])
               ^^^^^^^^^^^^^^^^^^^^^^^^^^^^^^^^^^^^^^^^^^^
  File "C:\Users\beyza.ozkara\ArslanDjango\env\Lib\site-packages\django\db\models\query.py", line 398, in __iter__
    self._fetch_all()
  File "C:\Users\beyza.ozkara\ArslanDjango\env\Lib\site-packages\django\db\models\query.py", line 1881, in _fetch_all
    self._result_cache = list(self._iterable_class(self))
                         ^^^^^^^^^^^^^^^^^^^^^^^^^^^^^^^^
  File "C:\Users\beyza.ozkara\ArslanDjango\env\Lib\site-packages\django\db\models\query.py", line 208, in __iter__
    for row in compiler.results_iter(
               ^^^^^^^^^^^^^^^^^^^^^^
  File "C:\Users\beyza.ozkara\ArslanDjango\env\Lib\site-packages\django\db\models\sql\compiler.py", line 1513, in results_iter
    results = self.execute_sql(
              ^^^^^^^^^^^^^^^^^
  File "C:\Users\beyza.ozkara\ArslanDjango\env\Lib\site-packages\django\db\models\sql\compiler.py", line 1562, in execute_sql
    cursor.execute(sql, params)
  File "C:\Users\beyza.ozkara\ArslanDjango\env\Lib\site-packages\django\db\backends\utils.py", line 102, in execute
    return super().execute(sql, params)
           ^^^^^^^^^^^^^^^^^^^^^^^^^^^^
  File "C:\Users\beyza.ozkara\ArslanDjango\env\Lib\site-packages\django\db\backends\utils.py", line 67, in execute
    return self._execute_with_wrappers(
           ^^^^^^^^^^^^^^^^^^^^^^^^^^^^
  File "C:\Users\beyza.ozkara\ArslanDjango\env\Lib\site-packages\django\db\backends\utils.py", line 80, in _execute_with_wrappers
    return executor(sql, params, many, context)
           ^^^^^^^^^^^^^^^^^^^^^^^^^^^^^^^^^^^^
  File "C:\Users\beyza.ozkara\ArslanDjango\env\Lib\site-packages\django\db\backends\utils.py", line 84, in _execute
    with self.db.wrap_database_errors:
  File "C:\Users\beyza.ozkara\ArslanDjango\env\Lib\site-packages\django\db\utils.py", line 91, in __exit__
    raise dj_exc_value.with_traceback(traceback) from exc_value
  File "C:\Users\beyza.ozkara\ArslanDjango\env\Lib\site-packages\django\db\backends\utils.py", line 89, in _execute
    return self.cursor.execute(sql, params)
           ^^^^^^^^^^^^^^^^^^^^^^^^^^^^^^^^
django.db.utils.ProgrammingError: column ArslanTakipApp_yudaform.Silindi does not exist
LINE 1: ...", "ArslanTakipApp_yudaform"."PaketlemeAciklama", "ArslanTak...
                                                             ^

"GET /yudas/list?params=%7B%22page%22%3A1%2C%22size%22%3A7%2C%22filter%22%3A%5B%5D%7D HTTP/1.1" 500 146715
Internal Server Error: /yudas/list
Traceback (most recent call last):
  File "C:\Users\beyza.ozkara\ArslanDjango\env\Lib\site-packages\django\db\backends\utils.py", line 89, in _execute
    return self.cursor.execute(sql, params)
           ^^^^^^^^^^^^^^^^^^^^^^^^^^^^^^^^
psycopg2.errors.UndefinedColumn: column ArslanTakipApp_yudaform.Silindi does not exist
LINE 1: ...", "ArslanTakipApp_yudaform"."PaketlemeAciklama", "ArslanTak...
                                                             ^


The above exception was the direct cause of the following exception:

Traceback (most recent call last):
  File "C:\Users\beyza.ozkara\ArslanDjango\env\Lib\site-packages\django\core\handlers\exception.py", line 55, in inner
    response = get_response(request)
               ^^^^^^^^^^^^^^^^^^^^^
  File "C:\Users\beyza.ozkara\ArslanDjango\env\Lib\site-packages\django\core\handlers\base.py", line 197, in _get_response
    response = wrapped_callback(request, *callback_args, **callback_kwargs)
               ^^^^^^^^^^^^^^^^^^^^^^^^^^^^^^^^^^^^^^^^^^^^^^^^^^^^^^^^^^^^
  File "C:\Users\beyza.ozkara\ArslanDjango\env\ArslanProject\ArslanTakipApp\views.py", line 1203, in yudas_list
    yudaList = list(filtered_yudas.values()[offset:limit])
               ^^^^^^^^^^^^^^^^^^^^^^^^^^^^^^^^^^^^^^^^^^^
  File "C:\Users\beyza.ozkara\ArslanDjango\env\Lib\site-packages\django\db\models\query.py", line 398, in __iter__
    self._fetch_all()
  File "C:\Users\beyza.ozkara\ArslanDjango\env\Lib\site-packages\django\db\models\query.py", line 1881, in _fetch_all
    self._result_cache = list(self._iterable_class(self))
                         ^^^^^^^^^^^^^^^^^^^^^^^^^^^^^^^^
  File "C:\Users\beyza.ozkara\ArslanDjango\env\Lib\site-packages\django\db\models\query.py", line 208, in __iter__
    for row in compiler.results_iter(
               ^^^^^^^^^^^^^^^^^^^^^^
  File "C:\Users\beyza.ozkara\ArslanDjango\env\Lib\site-packages\django\db\models\sql\compiler.py", line 1513, in results_iter
    results = self.execute_sql(
              ^^^^^^^^^^^^^^^^^
  File "C:\Users\beyza.ozkara\ArslanDjango\env\Lib\site-packages\django\db\models\sql\compiler.py", line 1562, in execute_sql
    cursor.execute(sql, params)
  File "C:\Users\beyza.ozkara\ArslanDjango\env\Lib\site-packages\django\db\backends\utils.py", line 102, in execute
    return super().execute(sql, params)
           ^^^^^^^^^^^^^^^^^^^^^^^^^^^^
  File "C:\Users\beyza.ozkara\ArslanDjango\env\Lib\site-packages\django\db\backends\utils.py", line 67, in execute
    return self._execute_with_wrappers(
           ^^^^^^^^^^^^^^^^^^^^^^^^^^^^
  File "C:\Users\beyza.ozkara\ArslanDjango\env\Lib\site-packages\django\db\backends\utils.py", line 80, in _execute_with_wrappers
    return executor(sql, params, many, context)
           ^^^^^^^^^^^^^^^^^^^^^^^^^^^^^^^^^^^^
  File "C:\Users\beyza.ozkara\ArslanDjango\env\Lib\site-packages\django\db\backends\utils.py", line 84, in _execute
    with self.db.wrap_database_errors:
  File "C:\Users\beyza.ozkara\ArslanDjango\env\Lib\site-packages\django\db\utils.py", line 91, in __exit__
    raise dj_exc_value.with_traceback(traceback) from exc_value
  File "C:\Users\beyza.ozkara\ArslanDjango\env\Lib\site-packages\django\db\backends\utils.py", line 89, in _execute
    return self.cursor.execute(sql, params)
           ^^^^^^^^^^^^^^^^^^^^^^^^^^^^^^^^
django.db.utils.ProgrammingError: column ArslanTakipApp_yudaform.Silindi does not exist
LINE 1: ...", "ArslanTakipApp_yudaform"."PaketlemeAciklama", "ArslanTak...
                                                             ^

"GET /yudas/list?params=%7B%22page%22%3A1%2C%22size%22%3A7%2C%22filter%22%3A%5B%5D%7D HTTP/1.1" 500 146715
Internal Server Error: /yudas/list
Traceback (most recent call last):
  File "C:\Users\beyza.ozkara\ArslanDjango\env\Lib\site-packages\django\db\backends\utils.py", line 89, in _execute
    return self.cursor.execute(sql, params)
           ^^^^^^^^^^^^^^^^^^^^^^^^^^^^^^^^
psycopg2.errors.UndefinedColumn: column ArslanTakipApp_yudaform.Silindi does not exist
LINE 1: ...", "ArslanTakipApp_yudaform"."PaketlemeAciklama", "ArslanTak...
                                                             ^


The above exception was the direct cause of the following exception:

Traceback (most recent call last):
  File "C:\Users\beyza.ozkara\ArslanDjango\env\Lib\site-packages\django\core\handlers\exception.py", line 55, in inner
    response = get_response(request)
               ^^^^^^^^^^^^^^^^^^^^^
  File "C:\Users\beyza.ozkara\ArslanDjango\env\Lib\site-packages\django\core\handlers\base.py", line 197, in _get_response
    response = wrapped_callback(request, *callback_args, **callback_kwargs)
               ^^^^^^^^^^^^^^^^^^^^^^^^^^^^^^^^^^^^^^^^^^^^^^^^^^^^^^^^^^^^
  File "C:\Users\beyza.ozkara\ArslanDjango\env\ArslanProject\ArslanTakipApp\views.py", line 1203, in yudas_list
    yudaList = list(filtered_yudas.values()[offset:limit])
               ^^^^^^^^^^^^^^^^^^^^^^^^^^^^^^^^^^^^^^^^^^^
  File "C:\Users\beyza.ozkara\ArslanDjango\env\Lib\site-packages\django\db\models\query.py", line 398, in __iter__
    self._fetch_all()
  File "C:\Users\beyza.ozkara\ArslanDjango\env\Lib\site-packages\django\db\models\query.py", line 1881, in _fetch_all
    self._result_cache = list(self._iterable_class(self))
                         ^^^^^^^^^^^^^^^^^^^^^^^^^^^^^^^^
  File "C:\Users\beyza.ozkara\ArslanDjango\env\Lib\site-packages\django\db\models\query.py", line 208, in __iter__
    for row in compiler.results_iter(
               ^^^^^^^^^^^^^^^^^^^^^^
  File "C:\Users\beyza.ozkara\ArslanDjango\env\Lib\site-packages\django\db\models\sql\compiler.py", line 1513, in results_iter
    results = self.execute_sql(
              ^^^^^^^^^^^^^^^^^
  File "C:\Users\beyza.ozkara\ArslanDjango\env\Lib\site-packages\django\db\models\sql\compiler.py", line 1562, in execute_sql
    cursor.execute(sql, params)
  File "C:\Users\beyza.ozkara\ArslanDjango\env\Lib\site-packages\django\db\backends\utils.py", line 102, in execute
    return super().execute(sql, params)
           ^^^^^^^^^^^^^^^^^^^^^^^^^^^^
  File "C:\Users\beyza.ozkara\ArslanDjango\env\Lib\site-packages\django\db\backends\utils.py", line 67, in execute
    return self._execute_with_wrappers(
           ^^^^^^^^^^^^^^^^^^^^^^^^^^^^
  File "C:\Users\beyza.ozkara\ArslanDjango\env\Lib\site-packages\django\db\backends\utils.py", line 80, in _execute_with_wrappers
    return executor(sql, params, many, context)
           ^^^^^^^^^^^^^^^^^^^^^^^^^^^^^^^^^^^^
  File "C:\Users\beyza.ozkara\ArslanDjango\env\Lib\site-packages\django\db\backends\utils.py", line 84, in _execute
    with self.db.wrap_database_errors:
  File "C:\Users\beyza.ozkara\ArslanDjango\env\Lib\site-packages\django\db\utils.py", line 91, in __exit__
    raise dj_exc_value.with_traceback(traceback) from exc_value
  File "C:\Users\beyza.ozkara\ArslanDjango\env\Lib\site-packages\django\db\backends\utils.py", line 89, in _execute
    return self.cursor.execute(sql, params)
           ^^^^^^^^^^^^^^^^^^^^^^^^^^^^^^^^
django.db.utils.ProgrammingError: column ArslanTakipApp_yudaform.Silindi does not exist
LINE 1: ...", "ArslanTakipApp_yudaform"."PaketlemeAciklama", "ArslanTak...
                                                             ^

"GET /yudas/list?params=%7B%22page%22%3A1%2C%22size%22%3A7%2C%22filter%22%3A%5B%5D%7D HTTP/1.1" 500 146715
