Internal Server Error: /yudaDetail/86
Traceback (most recent call last):
  File "C:\Users\beyza.ozkara\ArslanDjango\env\Lib\site-packages\django\core\handlers\exception.py", line 55, in inner
    response = get_response(request)
               ^^^^^^^^^^^^^^^^^^^^^
  File "C:\Users\beyza.ozkara\ArslanDjango\env\Lib\site-packages\django\core\handlers\base.py", line 197, in _get_response
    response = wrapped_callback(request, *callback_args, **callback_kwargs)
               ^^^^^^^^^^^^^^^^^^^^^^^^^^^^^^^^^^^^^^^^^^^^^^^^^^^^^^^^^^^^
  File "C:\Users\beyza.ozkara\ArslanDjango\env\ArslanProject\ArslanTakipApp\views.py", line 1365, in yudaDetail
    if not YudaOnay.objects.filter(Yuda_id = yId, Kullanici = request.user).first():
           ^^^^^^^^^^^^^^^^^^^^^^^^^^^^^^^^^^^^^^^^^^^^^^^^^^^^^^^^^^^^^^^^
  File "C:\Users\beyza.ozkara\ArslanDjango\env\Lib\site-packages\django\db\models\manager.py", line 87, in manager_method
    return getattr(self.get_queryset(), name)(*args, **kwargs)
           ^^^^^^^^^^^^^^^^^^^^^^^^^^^^^^^^^^^^^^^^^^^^^^^^^^^
  File "C:\Users\beyza.ozkara\ArslanDjango\env\Lib\site-packages\django\db\models\query.py", line 1436, in filter
    return self._filter_or_exclude(False, args, kwargs)
           ^^^^^^^^^^^^^^^^^^^^^^^^^^^^^^^^^^^^^^^^^^^^
  File "C:\Users\beyza.ozkara\ArslanDjango\env\Lib\site-packages\django\db\models\query.py", line 1454, in _filter_or_exclude
    clone._filter_or_exclude_inplace(negate, args, kwargs)
  File "C:\Users\beyza.ozkara\ArslanDjango\env\Lib\site-packages\django\db\models\query.py", line 1461, in _filter_or_exclude_inplace
    self._query.add_q(Q(*args, **kwargs))
  File "C:\Users\beyza.ozkara\ArslanDjango\env\Lib\site-packages\django\db\models\sql\query.py", line 1534, in add_q
    clause, _ = self._add_q(q_object, self.used_aliases)
                ^^^^^^^^^^^^^^^^^^^^^^^^^^^^^^^^^^^^^^^^
  File "C:\Users\beyza.ozkara\ArslanDjango\env\Lib\site-packages\django\db\models\sql\query.py", line 1565, in _add_q
    child_clause, needed_inner = self.build_filter(
                                 ^^^^^^^^^^^^^^^^^^
  File "C:\Users\beyza.ozkara\ArslanDjango\env\Lib\site-packages\django\db\models\sql\query.py", line 1415, in build_filter
    lookups, parts, reffed_expression = self.solve_lookup_type(arg, summarize)
                                        ^^^^^^^^^^^^^^^^^^^^^^^^^^^^^^^^^^^^^^
  File "C:\Users\beyza.ozkara\ArslanDjango\env\Lib\site-packages\django\db\models\sql\query.py", line 1225, in solve_lookup_type
    _, field, _, lookup_parts = self.names_to_path(lookup_splitted, self.get_meta())
                                ^^^^^^^^^^^^^^^^^^^^^^^^^^^^^^^^^^^^^^^^^^^^^^^^^^^^
  File "C:\Users\beyza.ozkara\ArslanDjango\env\Lib\site-packages\django\db\models\sql\query.py", line 1713, in names_to_path
    raise FieldError(
django.core.exceptions.FieldError: Cannot resolve keyword 'Kullanici' into field. Choices are: Group, Group_id, OnayDurumu, Tarih, Yuda, Yuda_id, id
"GET /yudaDetail/86 HTTP/1.1" 500 133393
